INFO:root:Бот стартовал
INFO:apscheduler.scheduler:Scheduler started
ERROR:telegram.ext.updater:Error while getting Updates: Conflict: terminated by other getUpdates request; make sure that only one bot instance is running
ERROR:telegram.ext.dispatcher:No error handlers are registered, logging exception.
Traceback (most recent call last):
  File "C:\Users\asus\AppData\Local\Programs\Python\Python39\lib\site-packages\telegram\ext\updater.py", line 520, in _network_loop_retry
    if not action_cb():
  File "C:\Users\asus\AppData\Local\Programs\Python\Python39\lib\site-packages\telegram\ext\updater.py", line 471, in polling_action_cb
    updates = self.bot.get_updates(
  File "C:\Users\asus\AppData\Local\Programs\Python\Python39\lib\site-packages\telegram\bot.py", line 127, in decorator
    result = func(*args, **kwargs)
  File "C:\Users\asus\AppData\Local\Programs\Python\Python39\lib\site-packages\telegram\bot.py", line 2761, in get_updates
    result = self._post(
  File "C:\Users\asus\AppData\Local\Programs\Python\Python39\lib\site-packages\telegram\bot.py", line 259, in _post
    return self.request.post(
  File "C:\Users\asus\AppData\Local\Programs\Python\Python39\lib\site-packages\telegram\utils\request.py", line 350, in post
    result = self._request_wrapper(
  File "C:\Users\asus\AppData\Local\Programs\Python\Python39\lib\site-packages\telegram\utils\request.py", line 277, in _request_wrapper
    raise Conflict(message)
telegram.error.Conflict: Conflict: terminated by other getUpdates request; make sure that only one bot instance is running
ERROR:telegram.ext.updater:Error while getting Updates: Conflict: terminated by other getUpdates request; make sure that only one bot instance is running
ERROR:telegram.ext.dispatcher:No error handlers are registered, logging exception.
Traceback (most recent call last):
  File "C:\Users\asus\AppData\Local\Programs\Python\Python39\lib\site-packages\telegram\ext\updater.py", line 520, in _network_loop_retry
    if not action_cb():
  File "C:\Users\asus\AppData\Local\Programs\Python\Python39\lib\site-packages\telegram\ext\updater.py", line 471, in polling_action_cb
    updates = self.bot.get_updates(
  File "C:\Users\asus\AppData\Local\Programs\Python\Python39\lib\site-packages\telegram\bot.py", line 127, in decorator
    result = func(*args, **kwargs)
  File "C:\Users\asus\AppData\Local\Programs\Python\Python39\lib\site-packages\telegram\bot.py", line 2761, in get_updates
    result = self._post(
  File "C:\Users\asus\AppData\Local\Programs\Python\Python39\lib\site-packages\telegram\bot.py", line 259, in _post
    return self.request.post(
  File "C:\Users\asus\AppData\Local\Programs\Python\Python39\lib\site-packages\telegram\utils\request.py", line 350, in post
    result = self._request_wrapper(
  File "C:\Users\asus\AppData\Local\Programs\Python\Python39\lib\site-packages\telegram\utils\request.py", line 277, in _request_wrapper
    raise Conflict(message)
telegram.error.Conflict: Conflict: terminated by other getUpdates request; make sure that only one bot instance is running
ERROR:telegram.ext.updater:Error while getting Updates: Conflict: terminated by other getUpdates request; make sure that only one bot instance is running
ERROR:telegram.ext.dispatcher:No error handlers are registered, logging exception.
Traceback (most recent call last):
  File "C:\Users\asus\AppData\Local\Programs\Python\Python39\lib\site-packages\telegram\ext\updater.py", line 520, in _network_loop_retry
    if not action_cb():
  File "C:\Users\asus\AppData\Local\Programs\Python\Python39\lib\site-packages\telegram\ext\updater.py", line 471, in polling_action_cb
    updates = self.bot.get_updates(
  File "C:\Users\asus\AppData\Local\Programs\Python\Python39\lib\site-packages\telegram\bot.py", line 127, in decorator
    result = func(*args, **kwargs)
  File "C:\Users\asus\AppData\Local\Programs\Python\Python39\lib\site-packages\telegram\bot.py", line 2761, in get_updates
    result = self._post(
  File "C:\Users\asus\AppData\Local\Programs\Python\Python39\lib\site-packages\telegram\bot.py", line 259, in _post
    return self.request.post(
  File "C:\Users\asus\AppData\Local\Programs\Python\Python39\lib\site-packages\telegram\utils\request.py", line 350, in post
    result = self._request_wrapper(
  File "C:\Users\asus\AppData\Local\Programs\Python\Python39\lib\site-packages\telegram\utils\request.py", line 277, in _request_wrapper
    raise Conflict(message)
telegram.error.Conflict: Conflict: terminated by other getUpdates request; make sure that only one bot instance is running
ERROR:telegram.ext.updater:Error while getting Updates: Conflict: terminated by other getUpdates request; make sure that only one bot instance is running
ERROR:telegram.ext.dispatcher:No error handlers are registered, logging exception.
Traceback (most recent call last):
  File "C:\Users\asus\AppData\Local\Programs\Python\Python39\lib\site-packages\telegram\ext\updater.py", line 520, in _network_loop_retry
    if not action_cb():
  File "C:\Users\asus\AppData\Local\Programs\Python\Python39\lib\site-packages\telegram\ext\updater.py", line 471, in polling_action_cb
    updates = self.bot.get_updates(
  File "C:\Users\asus\AppData\Local\Programs\Python\Python39\lib\site-packages\telegram\bot.py", line 127, in decorator
    result = func(*args, **kwargs)
  File "C:\Users\asus\AppData\Local\Programs\Python\Python39\lib\site-packages\telegram\bot.py", line 2761, in get_updates
    result = self._post(
  File "C:\Users\asus\AppData\Local\Programs\Python\Python39\lib\site-packages\telegram\bot.py", line 259, in _post
    return self.request.post(
  File "C:\Users\asus\AppData\Local\Programs\Python\Python39\lib\site-packages\telegram\utils\request.py", line 350, in post
    result = self._request_wrapper(
  File "C:\Users\asus\AppData\Local\Programs\Python\Python39\lib\site-packages\telegram\utils\request.py", line 277, in _request_wrapper
    raise Conflict(message)
telegram.error.Conflict: Conflict: terminated by other getUpdates request; make sure that only one bot instance is running
ERROR:telegram.ext.updater:Error while getting Updates: Conflict: terminated by other getUpdates request; make sure that only one bot instance is running
ERROR:telegram.ext.dispatcher:No error handlers are registered, logging exception.
Traceback (most recent call last):
  File "C:\Users\asus\AppData\Local\Programs\Python\Python39\lib\site-packages\telegram\ext\updater.py", line 520, in _network_loop_retry
    if not action_cb():
  File "C:\Users\asus\AppData\Local\Programs\Python\Python39\lib\site-packages\telegram\ext\updater.py", line 471, in polling_action_cb
    updates = self.bot.get_updates(
  File "C:\Users\asus\AppData\Local\Programs\Python\Python39\lib\site-packages\telegram\bot.py", line 127, in decorator
    result = func(*args, **kwargs)
  File "C:\Users\asus\AppData\Local\Programs\Python\Python39\lib\site-packages\telegram\bot.py", line 2761, in get_updates
    result = self._post(
  File "C:\Users\asus\AppData\Local\Programs\Python\Python39\lib\site-packages\telegram\bot.py", line 259, in _post
    return self.request.post(
  File "C:\Users\asus\AppData\Local\Programs\Python\Python39\lib\site-packages\telegram\utils\request.py", line 350, in post
    result = self._request_wrapper(
  File "C:\Users\asus\AppData\Local\Programs\Python\Python39\lib\site-packages\telegram\utils\request.py", line 277, in _request_wrapper
    raise Conflict(message)
telegram.error.Conflict: Conflict: terminated by other getUpdates request; make sure that only one bot instance is running
ERROR:telegram.ext.updater:Error while getting Updates: Conflict: terminated by other getUpdates request; make sure that only one bot instance is running
ERROR:telegram.ext.dispatcher:No error handlers are registered, logging exception.
Traceback (most recent call last):
  File "C:\Users\asus\AppData\Local\Programs\Python\Python39\lib\site-packages\telegram\ext\updater.py", line 520, in _network_loop_retry
    if not action_cb():
  File "C:\Users\asus\AppData\Local\Programs\Python\Python39\lib\site-packages\telegram\ext\updater.py", line 471, in polling_action_cb
    updates = self.bot.get_updates(
  File "C:\Users\asus\AppData\Local\Programs\Python\Python39\lib\site-packages\telegram\bot.py", line 127, in decorator
    result = func(*args, **kwargs)
  File "C:\Users\asus\AppData\Local\Programs\Python\Python39\lib\site-packages\telegram\bot.py", line 2761, in get_updates
    result = self._post(
  File "C:\Users\asus\AppData\Local\Programs\Python\Python39\lib\site-packages\telegram\bot.py", line 259, in _post
    return self.request.post(
  File "C:\Users\asus\AppData\Local\Programs\Python\Python39\lib\site-packages\telegram\utils\request.py", line 350, in post
    result = self._request_wrapper(
  File "C:\Users\asus\AppData\Local\Programs\Python\Python39\lib\site-packages\telegram\utils\request.py", line 277, in _request_wrapper
    raise Conflict(message)
telegram.error.Conflict: Conflict: terminated by other getUpdates request; make sure that only one bot instance is running
ERROR:telegram.ext.updater:Error while getting Updates: Conflict: terminated by other getUpdates request; make sure that only one bot instance is running
ERROR:telegram.ext.dispatcher:No error handlers are registered, logging exception.
Traceback (most recent call last):
  File "C:\Users\asus\AppData\Local\Programs\Python\Python39\lib\site-packages\telegram\ext\updater.py", line 520, in _network_loop_retry
    if not action_cb():
  File "C:\Users\asus\AppData\Local\Programs\Python\Python39\lib\site-packages\telegram\ext\updater.py", line 471, in polling_action_cb
    updates = self.bot.get_updates(
  File "C:\Users\asus\AppData\Local\Programs\Python\Python39\lib\site-packages\telegram\bot.py", line 127, in decorator
    result = func(*args, **kwargs)
  File "C:\Users\asus\AppData\Local\Programs\Python\Python39\lib\site-packages\telegram\bot.py", line 2761, in get_updates
    result = self._post(
  File "C:\Users\asus\AppData\Local\Programs\Python\Python39\lib\site-packages\telegram\bot.py", line 259, in _post
    return self.request.post(
  File "C:\Users\asus\AppData\Local\Programs\Python\Python39\lib\site-packages\telegram\utils\request.py", line 350, in post
    result = self._request_wrapper(
  File "C:\Users\asus\AppData\Local\Programs\Python\Python39\lib\site-packages\telegram\utils\request.py", line 277, in _request_wrapper
    raise Conflict(message)
telegram.error.Conflict: Conflict: terminated by other getUpdates request; make sure that only one bot instance is running
ERROR:telegram.ext.updater:Error while getting Updates: Conflict: terminated by other getUpdates request; make sure that only one bot instance is running
ERROR:telegram.ext.dispatcher:No error handlers are registered, logging exception.
Traceback (most recent call last):
  File "C:\Users\asus\AppData\Local\Programs\Python\Python39\lib\site-packages\telegram\ext\updater.py", line 520, in _network_loop_retry
    if not action_cb():
  File "C:\Users\asus\AppData\Local\Programs\Python\Python39\lib\site-packages\telegram\ext\updater.py", line 471, in polling_action_cb
    updates = self.bot.get_updates(
  File "C:\Users\asus\AppData\Local\Programs\Python\Python39\lib\site-packages\telegram\bot.py", line 127, in decorator
    result = func(*args, **kwargs)
  File "C:\Users\asus\AppData\Local\Programs\Python\Python39\lib\site-packages\telegram\bot.py", line 2761, in get_updates
    result = self._post(
  File "C:\Users\asus\AppData\Local\Programs\Python\Python39\lib\site-packages\telegram\bot.py", line 259, in _post
    return self.request.post(
  File "C:\Users\asus\AppData\Local\Programs\Python\Python39\lib\site-packages\telegram\utils\request.py", line 350, in post
    result = self._request_wrapper(
  File "C:\Users\asus\AppData\Local\Programs\Python\Python39\lib\site-packages\telegram\utils\request.py", line 277, in _request_wrapper
    raise Conflict(message)
telegram.error.Conflict: Conflict: terminated by other getUpdates request; make sure that only one bot instance is running
ERROR:telegram.ext.updater:Error while getting Updates: Conflict: terminated by other getUpdates request; make sure that only one bot instance is running
ERROR:telegram.ext.dispatcher:No error handlers are registered, logging exception.
Traceback (most recent call last):
  File "C:\Users\asus\AppData\Local\Programs\Python\Python39\lib\site-packages\telegram\ext\updater.py", line 520, in _network_loop_retry
    if not action_cb():
  File "C:\Users\asus\AppData\Local\Programs\Python\Python39\lib\site-packages\telegram\ext\updater.py", line 471, in polling_action_cb
    updates = self.bot.get_updates(
  File "C:\Users\asus\AppData\Local\Programs\Python\Python39\lib\site-packages\telegram\bot.py", line 127, in decorator
    result = func(*args, **kwargs)
  File "C:\Users\asus\AppData\Local\Programs\Python\Python39\lib\site-packages\telegram\bot.py", line 2761, in get_updates
    result = self._post(
  File "C:\Users\asus\AppData\Local\Programs\Python\Python39\lib\site-packages\telegram\bot.py", line 259, in _post
    return self.request.post(
  File "C:\Users\asus\AppData\Local\Programs\Python\Python39\lib\site-packages\telegram\utils\request.py", line 350, in post
    result = self._request_wrapper(
  File "C:\Users\asus\AppData\Local\Programs\Python\Python39\lib\site-packages\telegram\utils\request.py", line 277, in _request_wrapper
    raise Conflict(message)
telegram.error.Conflict: Conflict: terminated by other getUpdates request; make sure that only one bot instance is running
ERROR:telegram.ext.updater:Error while getting Updates: Conflict: terminated by other getUpdates request; make sure that only one bot instance is running
ERROR:telegram.ext.dispatcher:No error handlers are registered, logging exception.
Traceback (most recent call last):
  File "C:\Users\asus\AppData\Local\Programs\Python\Python39\lib\site-packages\telegram\ext\updater.py", line 520, in _network_loop_retry
    if not action_cb():
  File "C:\Users\asus\AppData\Local\Programs\Python\Python39\lib\site-packages\telegram\ext\updater.py", line 471, in polling_action_cb
    updates = self.bot.get_updates(
  File "C:\Users\asus\AppData\Local\Programs\Python\Python39\lib\site-packages\telegram\bot.py", line 127, in decorator
    result = func(*args, **kwargs)
  File "C:\Users\asus\AppData\Local\Programs\Python\Python39\lib\site-packages\telegram\bot.py", line 2761, in get_updates
    result = self._post(
  File "C:\Users\asus\AppData\Local\Programs\Python\Python39\lib\site-packages\telegram\bot.py", line 259, in _post
    return self.request.post(
  File "C:\Users\asus\AppData\Local\Programs\Python\Python39\lib\site-packages\telegram\utils\request.py", line 350, in post
    result = self._request_wrapper(
  File "C:\Users\asus\AppData\Local\Programs\Python\Python39\lib\site-packages\telegram\utils\request.py", line 277, in _request_wrapper
    raise Conflict(message)
telegram.error.Conflict: Conflict: terminated by other getUpdates request; make sure that only one bot instance is running
ERROR:telegram.ext.updater:Error while getting Updates: Conflict: terminated by other getUpdates request; make sure that only one bot instance is running
ERROR:telegram.ext.dispatcher:No error handlers are registered, logging exception.
Traceback (most recent call last):
  File "C:\Users\asus\AppData\Local\Programs\Python\Python39\lib\site-packages\telegram\ext\updater.py", line 520, in _network_loop_retry
    if not action_cb():
  File "C:\Users\asus\AppData\Local\Programs\Python\Python39\lib\site-packages\telegram\ext\updater.py", line 471, in polling_action_cb
    updates = self.bot.get_updates(
  File "C:\Users\asus\AppData\Local\Programs\Python\Python39\lib\site-packages\telegram\bot.py", line 127, in decorator
    result = func(*args, **kwargs)
  File "C:\Users\asus\AppData\Local\Programs\Python\Python39\lib\site-packages\telegram\bot.py", line 2761, in get_updates
    result = self._post(
  File "C:\Users\asus\AppData\Local\Programs\Python\Python39\lib\site-packages\telegram\bot.py", line 259, in _post
    return self.request.post(
  File "C:\Users\asus\AppData\Local\Programs\Python\Python39\lib\site-packages\telegram\utils\request.py", line 350, in post
    result = self._request_wrapper(
  File "C:\Users\asus\AppData\Local\Programs\Python\Python39\lib\site-packages\telegram\utils\request.py", line 277, in _request_wrapper
    raise Conflict(message)
telegram.error.Conflict: Conflict: terminated by other getUpdates request; make sure that only one bot instance is running
ERROR:telegram.ext.updater:Error while getting Updates: Conflict: terminated by other getUpdates request; make sure that only one bot instance is running
ERROR:telegram.ext.dispatcher:No error handlers are registered, logging exception.
Traceback (most recent call last):
  File "C:\Users\asus\AppData\Local\Programs\Python\Python39\lib\site-packages\telegram\ext\updater.py", line 520, in _network_loop_retry
    if not action_cb():
  File "C:\Users\asus\AppData\Local\Programs\Python\Python39\lib\site-packages\telegram\ext\updater.py", line 471, in polling_action_cb
    updates = self.bot.get_updates(
  File "C:\Users\asus\AppData\Local\Programs\Python\Python39\lib\site-packages\telegram\bot.py", line 127, in decorator
    result = func(*args, **kwargs)
  File "C:\Users\asus\AppData\Local\Programs\Python\Python39\lib\site-packages\telegram\bot.py", line 2761, in get_updates
    result = self._post(
  File "C:\Users\asus\AppData\Local\Programs\Python\Python39\lib\site-packages\telegram\bot.py", line 259, in _post
    return self.request.post(
  File "C:\Users\asus\AppData\Local\Programs\Python\Python39\lib\site-packages\telegram\utils\request.py", line 350, in post
    result = self._request_wrapper(
  File "C:\Users\asus\AppData\Local\Programs\Python\Python39\lib\site-packages\telegram\utils\request.py", line 277, in _request_wrapper
    raise Conflict(message)
telegram.error.Conflict: Conflict: terminated by other getUpdates request; make sure that only one bot instance is running
ERROR:telegram.ext.updater:Error while getting Updates: Conflict: terminated by other getUpdates request; make sure that only one bot instance is running
ERROR:telegram.ext.dispatcher:No error handlers are registered, logging exception.
Traceback (most recent call last):
  File "C:\Users\asus\AppData\Local\Programs\Python\Python39\lib\site-packages\telegram\ext\updater.py", line 520, in _network_loop_retry
    if not action_cb():
  File "C:\Users\asus\AppData\Local\Programs\Python\Python39\lib\site-packages\telegram\ext\updater.py", line 471, in polling_action_cb
    updates = self.bot.get_updates(
  File "C:\Users\asus\AppData\Local\Programs\Python\Python39\lib\site-packages\telegram\bot.py", line 127, in decorator
    result = func(*args, **kwargs)
  File "C:\Users\asus\AppData\Local\Programs\Python\Python39\lib\site-packages\telegram\bot.py", line 2761, in get_updates
    result = self._post(
  File "C:\Users\asus\AppData\Local\Programs\Python\Python39\lib\site-packages\telegram\bot.py", line 259, in _post
    return self.request.post(
  File "C:\Users\asus\AppData\Local\Programs\Python\Python39\lib\site-packages\telegram\utils\request.py", line 350, in post
    result = self._request_wrapper(
  File "C:\Users\asus\AppData\Local\Programs\Python\Python39\lib\site-packages\telegram\utils\request.py", line 277, in _request_wrapper
    raise Conflict(message)
telegram.error.Conflict: Conflict: terminated by other getUpdates request; make sure that only one bot instance is running
ERROR:telegram.ext.updater:Error while getting Updates: Conflict: terminated by other getUpdates request; make sure that only one bot instance is running
ERROR:telegram.ext.dispatcher:No error handlers are registered, logging exception.
Traceback (most recent call last):
  File "C:\Users\asus\AppData\Local\Programs\Python\Python39\lib\site-packages\telegram\ext\updater.py", line 520, in _network_loop_retry
    if not action_cb():
  File "C:\Users\asus\AppData\Local\Programs\Python\Python39\lib\site-packages\telegram\ext\updater.py", line 471, in polling_action_cb
    updates = self.bot.get_updates(
  File "C:\Users\asus\AppData\Local\Programs\Python\Python39\lib\site-packages\telegram\bot.py", line 127, in decorator
    result = func(*args, **kwargs)
  File "C:\Users\asus\AppData\Local\Programs\Python\Python39\lib\site-packages\telegram\bot.py", line 2761, in get_updates
    result = self._post(
  File "C:\Users\asus\AppData\Local\Programs\Python\Python39\lib\site-packages\telegram\bot.py", line 259, in _post
    return self.request.post(
  File "C:\Users\asus\AppData\Local\Programs\Python\Python39\lib\site-packages\telegram\utils\request.py", line 350, in post
    result = self._request_wrapper(
  File "C:\Users\asus\AppData\Local\Programs\Python\Python39\lib\site-packages\telegram\utils\request.py", line 277, in _request_wrapper
    raise Conflict(message)
telegram.error.Conflict: Conflict: terminated by other getUpdates request; make sure that only one bot instance is running
ERROR:telegram.ext.updater:Error while getting Updates: Conflict: terminated by other getUpdates request; make sure that only one bot instance is running
ERROR:telegram.ext.dispatcher:No error handlers are registered, logging exception.
Traceback (most recent call last):
  File "C:\Users\asus\AppData\Local\Programs\Python\Python39\lib\site-packages\telegram\ext\updater.py", line 520, in _network_loop_retry
    if not action_cb():
  File "C:\Users\asus\AppData\Local\Programs\Python\Python39\lib\site-packages\telegram\ext\updater.py", line 471, in polling_action_cb
    updates = self.bot.get_updates(
  File "C:\Users\asus\AppData\Local\Programs\Python\Python39\lib\site-packages\telegram\bot.py", line 127, in decorator
    result = func(*args, **kwargs)
  File "C:\Users\asus\AppData\Local\Programs\Python\Python39\lib\site-packages\telegram\bot.py", line 2761, in get_updates
    result = self._post(
  File "C:\Users\asus\AppData\Local\Programs\Python\Python39\lib\site-packages\telegram\bot.py", line 259, in _post
    return self.request.post(
  File "C:\Users\asus\AppData\Local\Programs\Python\Python39\lib\site-packages\telegram\utils\request.py", line 350, in post
    result = self._request_wrapper(
  File "C:\Users\asus\AppData\Local\Programs\Python\Python39\lib\site-packages\telegram\utils\request.py", line 277, in _request_wrapper
    raise Conflict(message)
telegram.error.Conflict: Conflict: terminated by other getUpdates request; make sure that only one bot instance is running
ERROR:telegram.ext.updater:Error while getting Updates: Conflict: terminated by other getUpdates request; make sure that only one bot instance is running
ERROR:telegram.ext.dispatcher:No error handlers are registered, logging exception.
Traceback (most recent call last):
  File "C:\Users\asus\AppData\Local\Programs\Python\Python39\lib\site-packages\telegram\ext\updater.py", line 520, in _network_loop_retry
    if not action_cb():
  File "C:\Users\asus\AppData\Local\Programs\Python\Python39\lib\site-packages\telegram\ext\updater.py", line 471, in polling_action_cb
    updates = self.bot.get_updates(
  File "C:\Users\asus\AppData\Local\Programs\Python\Python39\lib\site-packages\telegram\bot.py", line 127, in decorator
    result = func(*args, **kwargs)
  File "C:\Users\asus\AppData\Local\Programs\Python\Python39\lib\site-packages\telegram\bot.py", line 2761, in get_updates
    result = self._post(
  File "C:\Users\asus\AppData\Local\Programs\Python\Python39\lib\site-packages\telegram\bot.py", line 259, in _post
    return self.request.post(
  File "C:\Users\asus\AppData\Local\Programs\Python\Python39\lib\site-packages\telegram\utils\request.py", line 350, in post
    result = self._request_wrapper(
  File "C:\Users\asus\AppData\Local\Programs\Python\Python39\lib\site-packages\telegram\utils\request.py", line 277, in _request_wrapper
    raise Conflict(message)
telegram.error.Conflict: Conflict: terminated by other getUpdates request; make sure that only one bot instance is running
ERROR:telegram.ext.updater:Error while getting Updates: Conflict: terminated by other getUpdates request; make sure that only one bot instance is running
ERROR:telegram.ext.dispatcher:No error handlers are registered, logging exception.
Traceback (most recent call last):
  File "C:\Users\asus\AppData\Local\Programs\Python\Python39\lib\site-packages\telegram\ext\updater.py", line 520, in _network_loop_retry
    if not action_cb():
  File "C:\Users\asus\AppData\Local\Programs\Python\Python39\lib\site-packages\telegram\ext\updater.py", line 471, in polling_action_cb
    updates = self.bot.get_updates(
  File "C:\Users\asus\AppData\Local\Programs\Python\Python39\lib\site-packages\telegram\bot.py", line 127, in decorator
    result = func(*args, **kwargs)
  File "C:\Users\asus\AppData\Local\Programs\Python\Python39\lib\site-packages\telegram\bot.py", line 2761, in get_updates
    result = self._post(
  File "C:\Users\asus\AppData\Local\Programs\Python\Python39\lib\site-packages\telegram\bot.py", line 259, in _post
    return self.request.post(
  File "C:\Users\asus\AppData\Local\Programs\Python\Python39\lib\site-packages\telegram\utils\request.py", line 350, in post
    result = self._request_wrapper(
  File "C:\Users\asus\AppData\Local\Programs\Python\Python39\lib\site-packages\telegram\utils\request.py", line 277, in _request_wrapper
    raise Conflict(message)
telegram.error.Conflict: Conflict: terminated by other getUpdates request; make sure that only one bot instance is running
ERROR:telegram.ext.updater:Error while getting Updates: Conflict: terminated by other getUpdates request; make sure that only one bot instance is running
ERROR:telegram.ext.dispatcher:No error handlers are registered, logging exception.
Traceback (most recent call last):
  File "C:\Users\asus\AppData\Local\Programs\Python\Python39\lib\site-packages\telegram\ext\updater.py", line 520, in _network_loop_retry
    if not action_cb():
  File "C:\Users\asus\AppData\Local\Programs\Python\Python39\lib\site-packages\telegram\ext\updater.py", line 471, in polling_action_cb
    updates = self.bot.get_updates(
  File "C:\Users\asus\AppData\Local\Programs\Python\Python39\lib\site-packages\telegram\bot.py", line 127, in decorator
    result = func(*args, **kwargs)
  File "C:\Users\asus\AppData\Local\Programs\Python\Python39\lib\site-packages\telegram\bot.py", line 2761, in get_updates
    result = self._post(
  File "C:\Users\asus\AppData\Local\Programs\Python\Python39\lib\site-packages\telegram\bot.py", line 259, in _post
    return self.request.post(
  File "C:\Users\asus\AppData\Local\Programs\Python\Python39\lib\site-packages\telegram\utils\request.py", line 350, in post
    result = self._request_wrapper(
  File "C:\Users\asus\AppData\Local\Programs\Python\Python39\lib\site-packages\telegram\utils\request.py", line 277, in _request_wrapper
    raise Conflict(message)
telegram.error.Conflict: Conflict: terminated by other getUpdates request; make sure that only one bot instance is running
ERROR:telegram.ext.updater:Error while getting Updates: Conflict: terminated by other getUpdates request; make sure that only one bot instance is running
ERROR:telegram.ext.dispatcher:No error handlers are registered, logging exception.
Traceback (most recent call last):
  File "C:\Users\asus\AppData\Local\Programs\Python\Python39\lib\site-packages\telegram\ext\updater.py", line 520, in _network_loop_retry
    if not action_cb():
  File "C:\Users\asus\AppData\Local\Programs\Python\Python39\lib\site-packages\telegram\ext\updater.py", line 471, in polling_action_cb
    updates = self.bot.get_updates(
  File "C:\Users\asus\AppData\Local\Programs\Python\Python39\lib\site-packages\telegram\bot.py", line 127, in decorator
    result = func(*args, **kwargs)
  File "C:\Users\asus\AppData\Local\Programs\Python\Python39\lib\site-packages\telegram\bot.py", line 2761, in get_updates
    result = self._post(
  File "C:\Users\asus\AppData\Local\Programs\Python\Python39\lib\site-packages\telegram\bot.py", line 259, in _post
    return self.request.post(
  File "C:\Users\asus\AppData\Local\Programs\Python\Python39\lib\site-packages\telegram\utils\request.py", line 350, in post
    result = self._request_wrapper(
  File "C:\Users\asus\AppData\Local\Programs\Python\Python39\lib\site-packages\telegram\utils\request.py", line 277, in _request_wrapper
    raise Conflict(message)
telegram.error.Conflict: Conflict: terminated by other getUpdates request; make sure that only one bot instance is running
ERROR:telegram.ext.updater:Error while getting Updates: Conflict: terminated by other getUpdates request; make sure that only one bot instance is running
ERROR:telegram.ext.dispatcher:No error handlers are registered, logging exception.
Traceback (most recent call last):
  File "C:\Users\asus\AppData\Local\Programs\Python\Python39\lib\site-packages\telegram\ext\updater.py", line 520, in _network_loop_retry
    if not action_cb():
  File "C:\Users\asus\AppData\Local\Programs\Python\Python39\lib\site-packages\telegram\ext\updater.py", line 471, in polling_action_cb
    updates = self.bot.get_updates(
  File "C:\Users\asus\AppData\Local\Programs\Python\Python39\lib\site-packages\telegram\bot.py", line 127, in decorator
    result = func(*args, **kwargs)
  File "C:\Users\asus\AppData\Local\Programs\Python\Python39\lib\site-packages\telegram\bot.py", line 2761, in get_updates
    result = self._post(
  File "C:\Users\asus\AppData\Local\Programs\Python\Python39\lib\site-packages\telegram\bot.py", line 259, in _post
    return self.request.post(
  File "C:\Users\asus\AppData\Local\Programs\Python\Python39\lib\site-packages\telegram\utils\request.py", line 350, in post
    result = self._request_wrapper(
  File "C:\Users\asus\AppData\Local\Programs\Python\Python39\lib\site-packages\telegram\utils\request.py", line 277, in _request_wrapper
    raise Conflict(message)
telegram.error.Conflict: Conflict: terminated by other getUpdates request; make sure that only one bot instance is running
ERROR:telegram.ext.updater:Error while getting Updates: Conflict: terminated by other getUpdates request; make sure that only one bot instance is running
ERROR:telegram.ext.dispatcher:No error handlers are registered, logging exception.
Traceback (most recent call last):
  File "C:\Users\asus\AppData\Local\Programs\Python\Python39\lib\site-packages\telegram\ext\updater.py", line 520, in _network_loop_retry
    if not action_cb():
  File "C:\Users\asus\AppData\Local\Programs\Python\Python39\lib\site-packages\telegram\ext\updater.py", line 471, in polling_action_cb
    updates = self.bot.get_updates(
  File "C:\Users\asus\AppData\Local\Programs\Python\Python39\lib\site-packages\telegram\bot.py", line 127, in decorator
    result = func(*args, **kwargs)
  File "C:\Users\asus\AppData\Local\Programs\Python\Python39\lib\site-packages\telegram\bot.py", line 2761, in get_updates
    result = self._post(
  File "C:\Users\asus\AppData\Local\Programs\Python\Python39\lib\site-packages\telegram\bot.py", line 259, in _post
    return self.request.post(
  File "C:\Users\asus\AppData\Local\Programs\Python\Python39\lib\site-packages\telegram\utils\request.py", line 350, in post
    result = self._request_wrapper(
  File "C:\Users\asus\AppData\Local\Programs\Python\Python39\lib\site-packages\telegram\utils\request.py", line 277, in _request_wrapper
    raise Conflict(message)
telegram.error.Conflict: Conflict: terminated by other getUpdates request; make sure that only one bot instance is running
ERROR:telegram.ext.updater:Error while getting Updates: Conflict: terminated by other getUpdates request; make sure that only one bot instance is running
ERROR:telegram.ext.dispatcher:No error handlers are registered, logging exception.
Traceback (most recent call last):
  File "C:\Users\asus\AppData\Local\Programs\Python\Python39\lib\site-packages\telegram\ext\updater.py", line 520, in _network_loop_retry
    if not action_cb():
  File "C:\Users\asus\AppData\Local\Programs\Python\Python39\lib\site-packages\telegram\ext\updater.py", line 471, in polling_action_cb
    updates = self.bot.get_updates(
  File "C:\Users\asus\AppData\Local\Programs\Python\Python39\lib\site-packages\telegram\bot.py", line 127, in decorator
    result = func(*args, **kwargs)
  File "C:\Users\asus\AppData\Local\Programs\Python\Python39\lib\site-packages\telegram\bot.py", line 2761, in get_updates
    result = self._post(
  File "C:\Users\asus\AppData\Local\Programs\Python\Python39\lib\site-packages\telegram\bot.py", line 259, in _post
    return self.request.post(
  File "C:\Users\asus\AppData\Local\Programs\Python\Python39\lib\site-packages\telegram\utils\request.py", line 350, in post
    result = self._request_wrapper(
  File "C:\Users\asus\AppData\Local\Programs\Python\Python39\lib\site-packages\telegram\utils\request.py", line 277, in _request_wrapper
    raise Conflict(message)
telegram.error.Conflict: Conflict: terminated by other getUpdates request; make sure that only one bot instance is running
ERROR:telegram.ext.updater:Error while getting Updates: Conflict: terminated by other getUpdates request; make sure that only one bot instance is running
ERROR:telegram.ext.dispatcher:No error handlers are registered, logging exception.
Traceback (most recent call last):
  File "C:\Users\asus\AppData\Local\Programs\Python\Python39\lib\site-packages\telegram\ext\updater.py", line 520, in _network_loop_retry
    if not action_cb():
  File "C:\Users\asus\AppData\Local\Programs\Python\Python39\lib\site-packages\telegram\ext\updater.py", line 471, in polling_action_cb
    updates = self.bot.get_updates(
  File "C:\Users\asus\AppData\Local\Programs\Python\Python39\lib\site-packages\telegram\bot.py", line 127, in decorator
    result = func(*args, **kwargs)
  File "C:\Users\asus\AppData\Local\Programs\Python\Python39\lib\site-packages\telegram\bot.py", line 2761, in get_updates
    result = self._post(
  File "C:\Users\asus\AppData\Local\Programs\Python\Python39\lib\site-packages\telegram\bot.py", line 259, in _post
    return self.request.post(
  File "C:\Users\asus\AppData\Local\Programs\Python\Python39\lib\site-packages\telegram\utils\request.py", line 350, in post
    result = self._request_wrapper(
  File "C:\Users\asus\AppData\Local\Programs\Python\Python39\lib\site-packages\telegram\utils\request.py", line 277, in _request_wrapper
    raise Conflict(message)
telegram.error.Conflict: Conflict: terminated by other getUpdates request; make sure that only one bot instance is running
ERROR:telegram.ext.updater:Error while getting Updates: Conflict: terminated by other getUpdates request; make sure that only one bot instance is running
ERROR:telegram.ext.dispatcher:No error handlers are registered, logging exception.
Traceback (most recent call last):
  File "C:\Users\asus\AppData\Local\Programs\Python\Python39\lib\site-packages\telegram\ext\updater.py", line 520, in _network_loop_retry
    if not action_cb():
  File "C:\Users\asus\AppData\Local\Programs\Python\Python39\lib\site-packages\telegram\ext\updater.py", line 471, in polling_action_cb
    updates = self.bot.get_updates(
  File "C:\Users\asus\AppData\Local\Programs\Python\Python39\lib\site-packages\telegram\bot.py", line 127, in decorator
    result = func(*args, **kwargs)
  File "C:\Users\asus\AppData\Local\Programs\Python\Python39\lib\site-packages\telegram\bot.py", line 2761, in get_updates
    result = self._post(
  File "C:\Users\asus\AppData\Local\Programs\Python\Python39\lib\site-packages\telegram\bot.py", line 259, in _post
    return self.request.post(
  File "C:\Users\asus\AppData\Local\Programs\Python\Python39\lib\site-packages\telegram\utils\request.py", line 350, in post
    result = self._request_wrapper(
  File "C:\Users\asus\AppData\Local\Programs\Python\Python39\lib\site-packages\telegram\utils\request.py", line 277, in _request_wrapper
    raise Conflict(message)
telegram.error.Conflict: Conflict: terminated by other getUpdates request; make sure that only one bot instance is running
ERROR:telegram.ext.updater:Error while getting Updates: Conflict: terminated by other getUpdates request; make sure that only one bot instance is running
ERROR:telegram.ext.dispatcher:No error handlers are registered, logging exception.
Traceback (most recent call last):
  File "C:\Users\asus\AppData\Local\Programs\Python\Python39\lib\site-packages\telegram\ext\updater.py", line 520, in _network_loop_retry
    if not action_cb():
  File "C:\Users\asus\AppData\Local\Programs\Python\Python39\lib\site-packages\telegram\ext\updater.py", line 471, in polling_action_cb
    updates = self.bot.get_updates(
  File "C:\Users\asus\AppData\Local\Programs\Python\Python39\lib\site-packages\telegram\bot.py", line 127, in decorator
    result = func(*args, **kwargs)
  File "C:\Users\asus\AppData\Local\Programs\Python\Python39\lib\site-packages\telegram\bot.py", line 2761, in get_updates
    result = self._post(
  File "C:\Users\asus\AppData\Local\Programs\Python\Python39\lib\site-packages\telegram\bot.py", line 259, in _post
    return self.request.post(
  File "C:\Users\asus\AppData\Local\Programs\Python\Python39\lib\site-packages\telegram\utils\request.py", line 350, in post
    result = self._request_wrapper(
  File "C:\Users\asus\AppData\Local\Programs\Python\Python39\lib\site-packages\telegram\utils\request.py", line 277, in _request_wrapper
    raise Conflict(message)
telegram.error.Conflict: Conflict: terminated by other getUpdates request; make sure that only one bot instance is running
ERROR:telegram.ext.updater:Error while getting Updates: Conflict: terminated by other getUpdates request; make sure that only one bot instance is running
ERROR:telegram.ext.dispatcher:No error handlers are registered, logging exception.
Traceback (most recent call last):
  File "C:\Users\asus\AppData\Local\Programs\Python\Python39\lib\site-packages\telegram\ext\updater.py", line 520, in _network_loop_retry
    if not action_cb():
  File "C:\Users\asus\AppData\Local\Programs\Python\Python39\lib\site-packages\telegram\ext\updater.py", line 471, in polling_action_cb
    updates = self.bot.get_updates(
  File "C:\Users\asus\AppData\Local\Programs\Python\Python39\lib\site-packages\telegram\bot.py", line 127, in decorator
    result = func(*args, **kwargs)
  File "C:\Users\asus\AppData\Local\Programs\Python\Python39\lib\site-packages\telegram\bot.py", line 2761, in get_updates
    result = self._post(
  File "C:\Users\asus\AppData\Local\Programs\Python\Python39\lib\site-packages\telegram\bot.py", line 259, in _post
    return self.request.post(
  File "C:\Users\asus\AppData\Local\Programs\Python\Python39\lib\site-packages\telegram\utils\request.py", line 350, in post
    result = self._request_wrapper(
  File "C:\Users\asus\AppData\Local\Programs\Python\Python39\lib\site-packages\telegram\utils\request.py", line 277, in _request_wrapper
    raise Conflict(message)
telegram.error.Conflict: Conflict: terminated by other getUpdates request; make sure that only one bot instance is running
ERROR:telegram.ext.updater:Error while getting Updates: Conflict: terminated by other getUpdates request; make sure that only one bot instance is running
ERROR:telegram.ext.dispatcher:No error handlers are registered, logging exception.
Traceback (most recent call last):
  File "C:\Users\asus\AppData\Local\Programs\Python\Python39\lib\site-packages\telegram\ext\updater.py", line 520, in _network_loop_retry
    if not action_cb():
  File "C:\Users\asus\AppData\Local\Programs\Python\Python39\lib\site-packages\telegram\ext\updater.py", line 471, in polling_action_cb
    updates = self.bot.get_updates(
  File "C:\Users\asus\AppData\Local\Programs\Python\Python39\lib\site-packages\telegram\bot.py", line 127, in decorator
    result = func(*args, **kwargs)
  File "C:\Users\asus\AppData\Local\Programs\Python\Python39\lib\site-packages\telegram\bot.py", line 2761, in get_updates
    result = self._post(
  File "C:\Users\asus\AppData\Local\Programs\Python\Python39\lib\site-packages\telegram\bot.py", line 259, in _post
    return self.request.post(
  File "C:\Users\asus\AppData\Local\Programs\Python\Python39\lib\site-packages\telegram\utils\request.py", line 350, in post
    result = self._request_wrapper(
  File "C:\Users\asus\AppData\Local\Programs\Python\Python39\lib\site-packages\telegram\utils\request.py", line 277, in _request_wrapper
    raise Conflict(message)
telegram.error.Conflict: Conflict: terminated by other getUpdates request; make sure that only one bot instance is running
ERROR:telegram.ext.updater:Error while getting Updates: Conflict: terminated by other getUpdates request; make sure that only one bot instance is running
ERROR:telegram.ext.dispatcher:No error handlers are registered, logging exception.
Traceback (most recent call last):
  File "C:\Users\asus\AppData\Local\Programs\Python\Python39\lib\site-packages\telegram\ext\updater.py", line 520, in _network_loop_retry
    if not action_cb():
  File "C:\Users\asus\AppData\Local\Programs\Python\Python39\lib\site-packages\telegram\ext\updater.py", line 471, in polling_action_cb
    updates = self.bot.get_updates(
  File "C:\Users\asus\AppData\Local\Programs\Python\Python39\lib\site-packages\telegram\bot.py", line 127, in decorator
    result = func(*args, **kwargs)
  File "C:\Users\asus\AppData\Local\Programs\Python\Python39\lib\site-packages\telegram\bot.py", line 2761, in get_updates
    result = self._post(
  File "C:\Users\asus\AppData\Local\Programs\Python\Python39\lib\site-packages\telegram\bot.py", line 259, in _post
    return self.request.post(
  File "C:\Users\asus\AppData\Local\Programs\Python\Python39\lib\site-packages\telegram\utils\request.py", line 350, in post
    result = self._request_wrapper(
  File "C:\Users\asus\AppData\Local\Programs\Python\Python39\lib\site-packages\telegram\utils\request.py", line 277, in _request_wrapper
    raise Conflict(message)
telegram.error.Conflict: Conflict: terminated by other getUpdates request; make sure that only one bot instance is running
INFO:telegram.ext.updater:Received signal 2 (SIGINT), stopping...
INFO:apscheduler.scheduler:Scheduler has been shut down
INFO:root:Бот стартовал
INFO:apscheduler.scheduler:Scheduler started
WARNING:telegram.vendor.ptb_urllib3.urllib3.connectionpool:Retrying (Retry(total=2, connect=None, read=None, redirect=None)) after connection broken by 'NewConnectionError('<telegram.vendor.ptb_urllib3.urllib3.contrib.socks.SOCKSHTTPSConnection object at 0x000001F2B35BD0A0>: Failed to establish a new connection: 0x02: Connection not allowed by ruleset')': /bot1883749178:AAEuyYvIY7fSvJVN6dT7Jq6A0pv36vc1Eqw/getMe
WARNING:telegram.vendor.ptb_urllib3.urllib3.connectionpool:Retrying (Retry(total=1, connect=None, read=None, redirect=None)) after connection broken by 'NewConnectionError('<telegram.vendor.ptb_urllib3.urllib3.contrib.socks.SOCKSHTTPSConnection object at 0x000001F2B35BD460>: Failed to establish a new connection: 0x02: Connection not allowed by ruleset')': /bot1883749178:AAEuyYvIY7fSvJVN6dT7Jq6A0pv36vc1Eqw/getMe
WARNING:telegram.vendor.ptb_urllib3.urllib3.connectionpool:Retrying (Retry(total=0, connect=None, read=None, redirect=None)) after connection broken by 'NewConnectionError('<telegram.vendor.ptb_urllib3.urllib3.contrib.socks.SOCKSHTTPSConnection object at 0x000001F2B35BD760>: Failed to establish a new connection: 0x02: Connection not allowed by ruleset')': /bot1883749178:AAEuyYvIY7fSvJVN6dT7Jq6A0pv36vc1Eqw/getMe
INFO:root:Бот стартовал
INFO:apscheduler.scheduler:Scheduler started
WARNING:telegram.vendor.ptb_urllib3.urllib3.connectionpool:Retrying (Retry(total=2, connect=None, read=None, redirect=None)) after connection broken by 'NewConnectionError('<telegram.vendor.ptb_urllib3.urllib3.contrib.socks.SOCKSHTTPSConnection object at 0x000002CFB9ACC0A0>: Failed to establish a new connection: 0x02: Connection not allowed by ruleset')': /bot1883749178:AAEuyYvIY7fSvJVN6dT7Jq6A0pv36vc1Eqw/getMe
WARNING:telegram.vendor.ptb_urllib3.urllib3.connectionpool:Retrying (Retry(total=1, connect=None, read=None, redirect=None)) after connection broken by 'NewConnectionError('<telegram.vendor.ptb_urllib3.urllib3.contrib.socks.SOCKSHTTPSConnection object at 0x000002CFB9ACC460>: Failed to establish a new connection: 0x02: Connection not allowed by ruleset')': /bot1883749178:AAEuyYvIY7fSvJVN6dT7Jq6A0pv36vc1Eqw/getMe
WARNING:telegram.vendor.ptb_urllib3.urllib3.connectionpool:Retrying (Retry(total=0, connect=None, read=None, redirect=None)) after connection broken by 'NewConnectionError('<telegram.vendor.ptb_urllib3.urllib3.contrib.socks.SOCKSHTTPSConnection object at 0x000002CFB9ACC760>: Failed to establish a new connection: 0x02: Connection not allowed by ruleset')': /bot1883749178:AAEuyYvIY7fSvJVN6dT7Jq6A0pv36vc1Eqw/getMe
INFO:root:Бот стартовал
INFO:apscheduler.scheduler:Scheduler started
WARNING:telegram.vendor.ptb_urllib3.urllib3.connectionpool:Retrying (Retry(total=2, connect=None, read=None, redirect=None)) after connection broken by 'NewConnectionError('<telegram.vendor.ptb_urllib3.urllib3.contrib.socks.SOCKSHTTPSConnection object at 0x0000010CDEFEC0A0>: Failed to establish a new connection: 0x02: Connection not allowed by ruleset')': /bot1883749178:AAEuyYvIY7fSvJVN6dT7Jq6A0pv36vc1Eqw/getMe
WARNING:telegram.vendor.ptb_urllib3.urllib3.connectionpool:Retrying (Retry(total=1, connect=None, read=None, redirect=None)) after connection broken by 'NewConnectionError('<telegram.vendor.ptb_urllib3.urllib3.contrib.socks.SOCKSHTTPSConnection object at 0x0000010CDEFEC460>: Failed to establish a new connection: 0x02: Connection not allowed by ruleset')': /bot1883749178:AAEuyYvIY7fSvJVN6dT7Jq6A0pv36vc1Eqw/getMe
WARNING:telegram.vendor.ptb_urllib3.urllib3.connectionpool:Retrying (Retry(total=0, connect=None, read=None, redirect=None)) after connection broken by 'NewConnectionError('<telegram.vendor.ptb_urllib3.urllib3.contrib.socks.SOCKSHTTPSConnection object at 0x0000010CDEFEC760>: Failed to establish a new connection: 0x02: Connection not allowed by ruleset')': /bot1883749178:AAEuyYvIY7fSvJVN6dT7Jq6A0pv36vc1Eqw/getMe
INFO:root:Бот стартовал
INFO:apscheduler.scheduler:Scheduler started
WARNING:telegram.vendor.ptb_urllib3.urllib3.connectionpool:Retrying (Retry(total=2, connect=None, read=None, redirect=None)) after connection broken by 'NewConnectionError('<telegram.vendor.ptb_urllib3.urllib3.contrib.socks.SOCKSHTTPSConnection object at 0x000001FCCB1BC160>: Failed to establish a new connection: 0x02: Connection not allowed by ruleset')': /bot1883749178:AAEuyYvIY7fSvJVN6dT7Jq6A0pv36vc1Eqw/getMe
WARNING:telegram.vendor.ptb_urllib3.urllib3.connectionpool:Retrying (Retry(total=1, connect=None, read=None, redirect=None)) after connection broken by 'NewConnectionError('<telegram.vendor.ptb_urllib3.urllib3.contrib.socks.SOCKSHTTPSConnection object at 0x000001FCCB1BC520>: Failed to establish a new connection: 0x02: Connection not allowed by ruleset')': /bot1883749178:AAEuyYvIY7fSvJVN6dT7Jq6A0pv36vc1Eqw/getMe
WARNING:telegram.vendor.ptb_urllib3.urllib3.connectionpool:Retrying (Retry(total=0, connect=None, read=None, redirect=None)) after connection broken by 'NewConnectionError('<telegram.vendor.ptb_urllib3.urllib3.contrib.socks.SOCKSHTTPSConnection object at 0x000001FCCB1BC820>: Failed to establish a new connection: 0x02: Connection not allowed by ruleset')': /bot1883749178:AAEuyYvIY7fSvJVN6dT7Jq6A0pv36vc1Eqw/getMe
INFO:root:Бот стартовал
INFO:apscheduler.scheduler:Scheduler started
WARNING:telegram.vendor.ptb_urllib3.urllib3.connectionpool:Retrying (Retry(total=2, connect=None, read=None, redirect=None)) after connection broken by 'NewConnectionError('<telegram.vendor.ptb_urllib3.urllib3.contrib.socks.SOCKSHTTPSConnection object at 0x0000019EA540B160>: Failed to establish a new connection: 0x02: Connection not allowed by ruleset')': /bot1883749178:AAEuyYvIY7fSvJVN6dT7Jq6A0pv36vc1Eqw/getMe
WARNING:telegram.vendor.ptb_urllib3.urllib3.connectionpool:Retrying (Retry(total=1, connect=None, read=None, redirect=None)) after connection broken by 'NewConnectionError('<telegram.vendor.ptb_urllib3.urllib3.contrib.socks.SOCKSHTTPSConnection object at 0x0000019EA540B520>: Failed to establish a new connection: 0x02: Connection not allowed by ruleset')': /bot1883749178:AAEuyYvIY7fSvJVN6dT7Jq6A0pv36vc1Eqw/getMe
WARNING:telegram.vendor.ptb_urllib3.urllib3.connectionpool:Retrying (Retry(total=0, connect=None, read=None, redirect=None)) after connection broken by 'NewConnectionError('<telegram.vendor.ptb_urllib3.urllib3.contrib.socks.SOCKSHTTPSConnection object at 0x0000019EA540B820>: Failed to establish a new connection: 0x02: Connection not allowed by ruleset')': /bot1883749178:AAEuyYvIY7fSvJVN6dT7Jq6A0pv36vc1Eqw/getMe
INFO:root:Бот стартовал
INFO:apscheduler.scheduler:Scheduler started
WARNING:telegram.vendor.ptb_urllib3.urllib3.connectionpool:Retrying (Retry(total=2, connect=None, read=None, redirect=None)) after connection broken by 'NewConnectionError('<telegram.vendor.ptb_urllib3.urllib3.contrib.socks.SOCKSHTTPSConnection object at 0x000001EB60B3B160>: Failed to establish a new connection: 0x02: Connection not allowed by ruleset')': /bot1883749178:AAEuyYvIY7fSvJVN6dT7Jq6A0pv36vc1Eqw/getMe
WARNING:telegram.vendor.ptb_urllib3.urllib3.connectionpool:Retrying (Retry(total=1, connect=None, read=None, redirect=None)) after connection broken by 'NewConnectionError('<telegram.vendor.ptb_urllib3.urllib3.contrib.socks.SOCKSHTTPSConnection object at 0x000001EB60B3B520>: Failed to establish a new connection: 0x02: Connection not allowed by ruleset')': /bot1883749178:AAEuyYvIY7fSvJVN6dT7Jq6A0pv36vc1Eqw/getMe
WARNING:telegram.vendor.ptb_urllib3.urllib3.connectionpool:Retrying (Retry(total=0, connect=None, read=None, redirect=None)) after connection broken by 'NewConnectionError('<telegram.vendor.ptb_urllib3.urllib3.contrib.socks.SOCKSHTTPSConnection object at 0x000001EB60B3B820>: Failed to establish a new connection: 0x02: Connection not allowed by ruleset')': /bot1883749178:AAEuyYvIY7fSvJVN6dT7Jq6A0pv36vc1Eqw/getMe
INFO:root:Бот стартовал
INFO:apscheduler.scheduler:Scheduler started
WARNING:telegram.vendor.ptb_urllib3.urllib3.connectionpool:Retrying (Retry(total=2, connect=None, read=None, redirect=None)) after connection broken by 'NewConnectionError('<telegram.vendor.ptb_urllib3.urllib3.contrib.socks.SOCKSHTTPSConnection object at 0x000002E22B7EC160>: Failed to establish a new connection: 0x08: Address type not supported')': /bot1883749178:AAEuyYvIY7fSvJVN6dT7Jq6A0pv36vc1Eqw/getMe
WARNING:telegram.vendor.ptb_urllib3.urllib3.connectionpool:Retrying (Retry(total=1, connect=None, read=None, redirect=None)) after connection broken by 'NewConnectionError('<telegram.vendor.ptb_urllib3.urllib3.contrib.socks.SOCKSHTTPSConnection object at 0x000002E22B7EC550>: Failed to establish a new connection: 0x08: Address type not supported')': /bot1883749178:AAEuyYvIY7fSvJVN6dT7Jq6A0pv36vc1Eqw/getMe
WARNING:telegram.vendor.ptb_urllib3.urllib3.connectionpool:Retrying (Retry(total=0, connect=None, read=None, redirect=None)) after connection broken by 'NewConnectionError('<telegram.vendor.ptb_urllib3.urllib3.contrib.socks.SOCKSHTTPSConnection object at 0x000002E22B7EC850>: Failed to establish a new connection: 0x08: Address type not supported')': /bot1883749178:AAEuyYvIY7fSvJVN6dT7Jq6A0pv36vc1Eqw/getMe
INFO:root:Бот стартовал
INFO:apscheduler.scheduler:Scheduler started
WARNING:telegram.vendor.ptb_urllib3.urllib3.connectionpool:Retrying (Retry(total=2, connect=None, read=None, redirect=None)) after connection broken by 'NewConnectionError('<telegram.vendor.ptb_urllib3.urllib3.contrib.socks.SOCKSHTTPSConnection object at 0x0000024AA266C160>: Failed to establish a new connection: 0x02: Connection not allowed by ruleset')': /bot1883749178:AAEuyYvIY7fSvJVN6dT7Jq6A0pv36vc1Eqw/getMe
WARNING:telegram.vendor.ptb_urllib3.urllib3.connectionpool:Retrying (Retry(total=1, connect=None, read=None, redirect=None)) after connection broken by 'NewConnectionError('<telegram.vendor.ptb_urllib3.urllib3.contrib.socks.SOCKSHTTPSConnection object at 0x0000024AA266C520>: Failed to establish a new connection: 0x02: Connection not allowed by ruleset')': /bot1883749178:AAEuyYvIY7fSvJVN6dT7Jq6A0pv36vc1Eqw/getMe
WARNING:telegram.vendor.ptb_urllib3.urllib3.connectionpool:Retrying (Retry(total=0, connect=None, read=None, redirect=None)) after connection broken by 'NewConnectionError('<telegram.vendor.ptb_urllib3.urllib3.contrib.socks.SOCKSHTTPSConnection object at 0x0000024AA266C820>: Failed to establish a new connection: 0x02: Connection not allowed by ruleset')': /bot1883749178:AAEuyYvIY7fSvJVN6dT7Jq6A0pv36vc1Eqw/getMe
INFO:root:Бот стартовал
INFO:apscheduler.scheduler:Scheduler started
WARNING:telegram.vendor.ptb_urllib3.urllib3.connectionpool:Retrying (Retry(total=2, connect=None, read=None, redirect=None)) after connection broken by 'NewConnectionError('<telegram.vendor.ptb_urllib3.urllib3.contrib.socks.SOCKSHTTPSConnection object at 0x0000020F43CCC160>: Failed to establish a new connection: 0x02: Connection not allowed by ruleset')': /bot1883749178:AAEuyYvIY7fSvJVN6dT7Jq6A0pv36vc1Eqw/getMe
WARNING:telegram.vendor.ptb_urllib3.urllib3.connectionpool:Retrying (Retry(total=1, connect=None, read=None, redirect=None)) after connection broken by 'NewConnectionError('<telegram.vendor.ptb_urllib3.urllib3.contrib.socks.SOCKSHTTPSConnection object at 0x0000020F43CCC520>: Failed to establish a new connection: 0x02: Connection not allowed by ruleset')': /bot1883749178:AAEuyYvIY7fSvJVN6dT7Jq6A0pv36vc1Eqw/getMe
WARNING:telegram.vendor.ptb_urllib3.urllib3.connectionpool:Retrying (Retry(total=0, connect=None, read=None, redirect=None)) after connection broken by 'NewConnectionError('<telegram.vendor.ptb_urllib3.urllib3.contrib.socks.SOCKSHTTPSConnection object at 0x0000020F43CCC820>: Failed to establish a new connection: 0x02: Connection not allowed by ruleset')': /bot1883749178:AAEuyYvIY7fSvJVN6dT7Jq6A0pv36vc1Eqw/getMe
