INFO:root:Бот стартовал
INFO:apscheduler.scheduler:Scheduler started
ERROR:telegram.ext.updater:Error while getting Updates: Conflict: terminated by other getUpdates request; make sure that only one bot instance is running
ERROR:telegram.ext.dispatcher:No error handlers are registered, logging exception.
Traceback (most recent call last):
  File "C:\Users\asus\AppData\Local\Programs\Python\Python39\lib\site-packages\telegram\ext\updater.py", line 520, in _network_loop_retry
    if not action_cb():
  File "C:\Users\asus\AppData\Local\Programs\Python\Python39\lib\site-packages\telegram\ext\updater.py", line 471, in polling_action_cb
    updates = self.bot.get_updates(
  File "C:\Users\asus\AppData\Local\Programs\Python\Python39\lib\site-packages\telegram\bot.py", line 127, in decorator
    result = func(*args, **kwargs)
  File "C:\Users\asus\AppData\Local\Programs\Python\Python39\lib\site-packages\telegram\bot.py", line 2761, in get_updates
    result = self._post(
  File "C:\Users\asus\AppData\Local\Programs\Python\Python39\lib\site-packages\telegram\bot.py", line 259, in _post
    return self.request.post(
  File "C:\Users\asus\AppData\Local\Programs\Python\Python39\lib\site-packages\telegram\utils\request.py", line 350, in post
    result = self._request_wrapper(
  File "C:\Users\asus\AppData\Local\Programs\Python\Python39\lib\site-packages\telegram\utils\request.py", line 277, in _request_wrapper
    raise Conflict(message)
telegram.error.Conflict: Conflict: terminated by other getUpdates request; make sure that only one bot instance is running
ERROR:telegram.ext.updater:Error while getting Updates: Conflict: terminated by other getUpdates request; make sure that only one bot instance is running
ERROR:telegram.ext.dispatcher:No error handlers are registered, logging exception.
Traceback (most recent call last):
  File "C:\Users\asus\AppData\Local\Programs\Python\Python39\lib\site-packages\telegram\ext\updater.py", line 520, in _network_loop_retry
    if not action_cb():
  File "C:\Users\asus\AppData\Local\Programs\Python\Python39\lib\site-packages\telegram\ext\updater.py", line 471, in polling_action_cb
    updates = self.bot.get_updates(
  File "C:\Users\asus\AppData\Local\Programs\Python\Python39\lib\site-packages\telegram\bot.py", line 127, in decorator
    result = func(*args, **kwargs)
  File "C:\Users\asus\AppData\Local\Programs\Python\Python39\lib\site-packages\telegram\bot.py", line 2761, in get_updates
    result = self._post(
  File "C:\Users\asus\AppData\Local\Programs\Python\Python39\lib\site-packages\telegram\bot.py", line 259, in _post
    return self.request.post(
  File "C:\Users\asus\AppData\Local\Programs\Python\Python39\lib\site-packages\telegram\utils\request.py", line 350, in post
    result = self._request_wrapper(
  File "C:\Users\asus\AppData\Local\Programs\Python\Python39\lib\site-packages\telegram\utils\request.py", line 277, in _request_wrapper
    raise Conflict(message)
telegram.error.Conflict: Conflict: terminated by other getUpdates request; make sure that only one bot instance is running
ERROR:telegram.ext.updater:Error while getting Updates: Conflict: terminated by other getUpdates request; make sure that only one bot instance is running
ERROR:telegram.ext.dispatcher:No error handlers are registered, logging exception.
Traceback (most recent call last):
  File "C:\Users\asus\AppData\Local\Programs\Python\Python39\lib\site-packages\telegram\ext\updater.py", line 520, in _network_loop_retry
    if not action_cb():
  File "C:\Users\asus\AppData\Local\Programs\Python\Python39\lib\site-packages\telegram\ext\updater.py", line 471, in polling_action_cb
    updates = self.bot.get_updates(
  File "C:\Users\asus\AppData\Local\Programs\Python\Python39\lib\site-packages\telegram\bot.py", line 127, in decorator
    result = func(*args, **kwargs)
  File "C:\Users\asus\AppData\Local\Programs\Python\Python39\lib\site-packages\telegram\bot.py", line 2761, in get_updates
    result = self._post(
  File "C:\Users\asus\AppData\Local\Programs\Python\Python39\lib\site-packages\telegram\bot.py", line 259, in _post
    return self.request.post(
  File "C:\Users\asus\AppData\Local\Programs\Python\Python39\lib\site-packages\telegram\utils\request.py", line 350, in post
    result = self._request_wrapper(
  File "C:\Users\asus\AppData\Local\Programs\Python\Python39\lib\site-packages\telegram\utils\request.py", line 277, in _request_wrapper
    raise Conflict(message)
telegram.error.Conflict: Conflict: terminated by other getUpdates request; make sure that only one bot instance is running
ERROR:telegram.ext.updater:Error while getting Updates: Conflict: terminated by other getUpdates request; make sure that only one bot instance is running
ERROR:telegram.ext.dispatcher:No error handlers are registered, logging exception.
Traceback (most recent call last):
  File "C:\Users\asus\AppData\Local\Programs\Python\Python39\lib\site-packages\telegram\ext\updater.py", line 520, in _network_loop_retry
    if not action_cb():
  File "C:\Users\asus\AppData\Local\Programs\Python\Python39\lib\site-packages\telegram\ext\updater.py", line 471, in polling_action_cb
    updates = self.bot.get_updates(
  File "C:\Users\asus\AppData\Local\Programs\Python\Python39\lib\site-packages\telegram\bot.py", line 127, in decorator
    result = func(*args, **kwargs)
  File "C:\Users\asus\AppData\Local\Programs\Python\Python39\lib\site-packages\telegram\bot.py", line 2761, in get_updates
    result = self._post(
  File "C:\Users\asus\AppData\Local\Programs\Python\Python39\lib\site-packages\telegram\bot.py", line 259, in _post
    return self.request.post(
  File "C:\Users\asus\AppData\Local\Programs\Python\Python39\lib\site-packages\telegram\utils\request.py", line 350, in post
    result = self._request_wrapper(
  File "C:\Users\asus\AppData\Local\Programs\Python\Python39\lib\site-packages\telegram\utils\request.py", line 277, in _request_wrapper
    raise Conflict(message)
telegram.error.Conflict: Conflict: terminated by other getUpdates request; make sure that only one bot instance is running
ERROR:telegram.ext.updater:Error while getting Updates: Conflict: terminated by other getUpdates request; make sure that only one bot instance is running
ERROR:telegram.ext.dispatcher:No error handlers are registered, logging exception.
Traceback (most recent call last):
  File "C:\Users\asus\AppData\Local\Programs\Python\Python39\lib\site-packages\telegram\ext\updater.py", line 520, in _network_loop_retry
    if not action_cb():
  File "C:\Users\asus\AppData\Local\Programs\Python\Python39\lib\site-packages\telegram\ext\updater.py", line 471, in polling_action_cb
    updates = self.bot.get_updates(
  File "C:\Users\asus\AppData\Local\Programs\Python\Python39\lib\site-packages\telegram\bot.py", line 127, in decorator
    result = func(*args, **kwargs)
  File "C:\Users\asus\AppData\Local\Programs\Python\Python39\lib\site-packages\telegram\bot.py", line 2761, in get_updates
    result = self._post(
  File "C:\Users\asus\AppData\Local\Programs\Python\Python39\lib\site-packages\telegram\bot.py", line 259, in _post
    return self.request.post(
  File "C:\Users\asus\AppData\Local\Programs\Python\Python39\lib\site-packages\telegram\utils\request.py", line 350, in post
    result = self._request_wrapper(
  File "C:\Users\asus\AppData\Local\Programs\Python\Python39\lib\site-packages\telegram\utils\request.py", line 277, in _request_wrapper
    raise Conflict(message)
telegram.error.Conflict: Conflict: terminated by other getUpdates request; make sure that only one bot instance is running
ERROR:telegram.ext.updater:Error while getting Updates: Conflict: terminated by other getUpdates request; make sure that only one bot instance is running
ERROR:telegram.ext.dispatcher:No error handlers are registered, logging exception.
Traceback (most recent call last):
  File "C:\Users\asus\AppData\Local\Programs\Python\Python39\lib\site-packages\telegram\ext\updater.py", line 520, in _network_loop_retry
    if not action_cb():
  File "C:\Users\asus\AppData\Local\Programs\Python\Python39\lib\site-packages\telegram\ext\updater.py", line 471, in polling_action_cb
    updates = self.bot.get_updates(
  File "C:\Users\asus\AppData\Local\Programs\Python\Python39\lib\site-packages\telegram\bot.py", line 127, in decorator
    result = func(*args, **kwargs)
  File "C:\Users\asus\AppData\Local\Programs\Python\Python39\lib\site-packages\telegram\bot.py", line 2761, in get_updates
    result = self._post(
  File "C:\Users\asus\AppData\Local\Programs\Python\Python39\lib\site-packages\telegram\bot.py", line 259, in _post
    return self.request.post(
  File "C:\Users\asus\AppData\Local\Programs\Python\Python39\lib\site-packages\telegram\utils\request.py", line 350, in post
    result = self._request_wrapper(
  File "C:\Users\asus\AppData\Local\Programs\Python\Python39\lib\site-packages\telegram\utils\request.py", line 277, in _request_wrapper
    raise Conflict(message)
telegram.error.Conflict: Conflict: terminated by other getUpdates request; make sure that only one bot instance is running
ERROR:telegram.ext.updater:Error while getting Updates: Conflict: terminated by other getUpdates request; make sure that only one bot instance is running
ERROR:telegram.ext.dispatcher:No error handlers are registered, logging exception.
Traceback (most recent call last):
  File "C:\Users\asus\AppData\Local\Programs\Python\Python39\lib\site-packages\telegram\ext\updater.py", line 520, in _network_loop_retry
    if not action_cb():
  File "C:\Users\asus\AppData\Local\Programs\Python\Python39\lib\site-packages\telegram\ext\updater.py", line 471, in polling_action_cb
    updates = self.bot.get_updates(
  File "C:\Users\asus\AppData\Local\Programs\Python\Python39\lib\site-packages\telegram\bot.py", line 127, in decorator
    result = func(*args, **kwargs)
  File "C:\Users\asus\AppData\Local\Programs\Python\Python39\lib\site-packages\telegram\bot.py", line 2761, in get_updates
    result = self._post(
  File "C:\Users\asus\AppData\Local\Programs\Python\Python39\lib\site-packages\telegram\bot.py", line 259, in _post
    return self.request.post(
  File "C:\Users\asus\AppData\Local\Programs\Python\Python39\lib\site-packages\telegram\utils\request.py", line 350, in post
    result = self._request_wrapper(
  File "C:\Users\asus\AppData\Local\Programs\Python\Python39\lib\site-packages\telegram\utils\request.py", line 277, in _request_wrapper
    raise Conflict(message)
telegram.error.Conflict: Conflict: terminated by other getUpdates request; make sure that only one bot instance is running
ERROR:telegram.ext.updater:Error while getting Updates: Conflict: terminated by other getUpdates request; make sure that only one bot instance is running
ERROR:telegram.ext.dispatcher:No error handlers are registered, logging exception.
Traceback (most recent call last):
  File "C:\Users\asus\AppData\Local\Programs\Python\Python39\lib\site-packages\telegram\ext\updater.py", line 520, in _network_loop_retry
    if not action_cb():
  File "C:\Users\asus\AppData\Local\Programs\Python\Python39\lib\site-packages\telegram\ext\updater.py", line 471, in polling_action_cb
    updates = self.bot.get_updates(
  File "C:\Users\asus\AppData\Local\Programs\Python\Python39\lib\site-packages\telegram\bot.py", line 127, in decorator
    result = func(*args, **kwargs)
  File "C:\Users\asus\AppData\Local\Programs\Python\Python39\lib\site-packages\telegram\bot.py", line 2761, in get_updates
    result = self._post(
  File "C:\Users\asus\AppData\Local\Programs\Python\Python39\lib\site-packages\telegram\bot.py", line 259, in _post
    return self.request.post(
  File "C:\Users\asus\AppData\Local\Programs\Python\Python39\lib\site-packages\telegram\utils\request.py", line 350, in post
    result = self._request_wrapper(
  File "C:\Users\asus\AppData\Local\Programs\Python\Python39\lib\site-packages\telegram\utils\request.py", line 277, in _request_wrapper
    raise Conflict(message)
telegram.error.Conflict: Conflict: terminated by other getUpdates request; make sure that only one bot instance is running
ERROR:telegram.ext.updater:Error while getting Updates: Conflict: terminated by other getUpdates request; make sure that only one bot instance is running
ERROR:telegram.ext.dispatcher:No error handlers are registered, logging exception.
Traceback (most recent call last):
  File "C:\Users\asus\AppData\Local\Programs\Python\Python39\lib\site-packages\telegram\ext\updater.py", line 520, in _network_loop_retry
    if not action_cb():
  File "C:\Users\asus\AppData\Local\Programs\Python\Python39\lib\site-packages\telegram\ext\updater.py", line 471, in polling_action_cb
    updates = self.bot.get_updates(
  File "C:\Users\asus\AppData\Local\Programs\Python\Python39\lib\site-packages\telegram\bot.py", line 127, in decorator
    result = func(*args, **kwargs)
  File "C:\Users\asus\AppData\Local\Programs\Python\Python39\lib\site-packages\telegram\bot.py", line 2761, in get_updates
    result = self._post(
  File "C:\Users\asus\AppData\Local\Programs\Python\Python39\lib\site-packages\telegram\bot.py", line 259, in _post
    return self.request.post(
  File "C:\Users\asus\AppData\Local\Programs\Python\Python39\lib\site-packages\telegram\utils\request.py", line 350, in post
    result = self._request_wrapper(
  File "C:\Users\asus\AppData\Local\Programs\Python\Python39\lib\site-packages\telegram\utils\request.py", line 277, in _request_wrapper
    raise Conflict(message)
telegram.error.Conflict: Conflict: terminated by other getUpdates request; make sure that only one bot instance is running
ERROR:telegram.ext.updater:Error while getting Updates: Conflict: terminated by other getUpdates request; make sure that only one bot instance is running
ERROR:telegram.ext.dispatcher:No error handlers are registered, logging exception.
Traceback (most recent call last):
  File "C:\Users\asus\AppData\Local\Programs\Python\Python39\lib\site-packages\telegram\ext\updater.py", line 520, in _network_loop_retry
    if not action_cb():
  File "C:\Users\asus\AppData\Local\Programs\Python\Python39\lib\site-packages\telegram\ext\updater.py", line 471, in polling_action_cb
    updates = self.bot.get_updates(
  File "C:\Users\asus\AppData\Local\Programs\Python\Python39\lib\site-packages\telegram\bot.py", line 127, in decorator
    result = func(*args, **kwargs)
  File "C:\Users\asus\AppData\Local\Programs\Python\Python39\lib\site-packages\telegram\bot.py", line 2761, in get_updates
    result = self._post(
  File "C:\Users\asus\AppData\Local\Programs\Python\Python39\lib\site-packages\telegram\bot.py", line 259, in _post
    return self.request.post(
  File "C:\Users\asus\AppData\Local\Programs\Python\Python39\lib\site-packages\telegram\utils\request.py", line 350, in post
    result = self._request_wrapper(
  File "C:\Users\asus\AppData\Local\Programs\Python\Python39\lib\site-packages\telegram\utils\request.py", line 277, in _request_wrapper
    raise Conflict(message)
telegram.error.Conflict: Conflict: terminated by other getUpdates request; make sure that only one bot instance is running
ERROR:telegram.ext.updater:Error while getting Updates: Conflict: terminated by other getUpdates request; make sure that only one bot instance is running
ERROR:telegram.ext.dispatcher:No error handlers are registered, logging exception.
Traceback (most recent call last):
  File "C:\Users\asus\AppData\Local\Programs\Python\Python39\lib\site-packages\telegram\ext\updater.py", line 520, in _network_loop_retry
    if not action_cb():
  File "C:\Users\asus\AppData\Local\Programs\Python\Python39\lib\site-packages\telegram\ext\updater.py", line 471, in polling_action_cb
    updates = self.bot.get_updates(
  File "C:\Users\asus\AppData\Local\Programs\Python\Python39\lib\site-packages\telegram\bot.py", line 127, in decorator
    result = func(*args, **kwargs)
  File "C:\Users\asus\AppData\Local\Programs\Python\Python39\lib\site-packages\telegram\bot.py", line 2761, in get_updates
    result = self._post(
  File "C:\Users\asus\AppData\Local\Programs\Python\Python39\lib\site-packages\telegram\bot.py", line 259, in _post
    return self.request.post(
  File "C:\Users\asus\AppData\Local\Programs\Python\Python39\lib\site-packages\telegram\utils\request.py", line 350, in post
    result = self._request_wrapper(
  File "C:\Users\asus\AppData\Local\Programs\Python\Python39\lib\site-packages\telegram\utils\request.py", line 277, in _request_wrapper
    raise Conflict(message)
telegram.error.Conflict: Conflict: terminated by other getUpdates request; make sure that only one bot instance is running
ERROR:telegram.ext.updater:Error while getting Updates: Conflict: terminated by other getUpdates request; make sure that only one bot instance is running
ERROR:telegram.ext.dispatcher:No error handlers are registered, logging exception.
Traceback (most recent call last):
  File "C:\Users\asus\AppData\Local\Programs\Python\Python39\lib\site-packages\telegram\ext\updater.py", line 520, in _network_loop_retry
    if not action_cb():
  File "C:\Users\asus\AppData\Local\Programs\Python\Python39\lib\site-packages\telegram\ext\updater.py", line 471, in polling_action_cb
    updates = self.bot.get_updates(
  File "C:\Users\asus\AppData\Local\Programs\Python\Python39\lib\site-packages\telegram\bot.py", line 127, in decorator
    result = func(*args, **kwargs)
  File "C:\Users\asus\AppData\Local\Programs\Python\Python39\lib\site-packages\telegram\bot.py", line 2761, in get_updates
    result = self._post(
  File "C:\Users\asus\AppData\Local\Programs\Python\Python39\lib\site-packages\telegram\bot.py", line 259, in _post
    return self.request.post(
  File "C:\Users\asus\AppData\Local\Programs\Python\Python39\lib\site-packages\telegram\utils\request.py", line 350, in post
    result = self._request_wrapper(
  File "C:\Users\asus\AppData\Local\Programs\Python\Python39\lib\site-packages\telegram\utils\request.py", line 277, in _request_wrapper
    raise Conflict(message)
telegram.error.Conflict: Conflict: terminated by other getUpdates request; make sure that only one bot instance is running
ERROR:telegram.ext.updater:Error while getting Updates: Conflict: terminated by other getUpdates request; make sure that only one bot instance is running
ERROR:telegram.ext.dispatcher:No error handlers are registered, logging exception.
Traceback (most recent call last):
  File "C:\Users\asus\AppData\Local\Programs\Python\Python39\lib\site-packages\telegram\ext\updater.py", line 520, in _network_loop_retry
    if not action_cb():
  File "C:\Users\asus\AppData\Local\Programs\Python\Python39\lib\site-packages\telegram\ext\updater.py", line 471, in polling_action_cb
    updates = self.bot.get_updates(
  File "C:\Users\asus\AppData\Local\Programs\Python\Python39\lib\site-packages\telegram\bot.py", line 127, in decorator
    result = func(*args, **kwargs)
  File "C:\Users\asus\AppData\Local\Programs\Python\Python39\lib\site-packages\telegram\bot.py", line 2761, in get_updates
    result = self._post(
  File "C:\Users\asus\AppData\Local\Programs\Python\Python39\lib\site-packages\telegram\bot.py", line 259, in _post
    return self.request.post(
  File "C:\Users\asus\AppData\Local\Programs\Python\Python39\lib\site-packages\telegram\utils\request.py", line 350, in post
    result = self._request_wrapper(
  File "C:\Users\asus\AppData\Local\Programs\Python\Python39\lib\site-packages\telegram\utils\request.py", line 277, in _request_wrapper
    raise Conflict(message)
telegram.error.Conflict: Conflict: terminated by other getUpdates request; make sure that only one bot instance is running
ERROR:telegram.ext.updater:Error while getting Updates: Conflict: terminated by other getUpdates request; make sure that only one bot instance is running
ERROR:telegram.ext.dispatcher:No error handlers are registered, logging exception.
Traceback (most recent call last):
  File "C:\Users\asus\AppData\Local\Programs\Python\Python39\lib\site-packages\telegram\ext\updater.py", line 520, in _network_loop_retry
    if not action_cb():
  File "C:\Users\asus\AppData\Local\Programs\Python\Python39\lib\site-packages\telegram\ext\updater.py", line 471, in polling_action_cb
    updates = self.bot.get_updates(
  File "C:\Users\asus\AppData\Local\Programs\Python\Python39\lib\site-packages\telegram\bot.py", line 127, in decorator
    result = func(*args, **kwargs)
  File "C:\Users\asus\AppData\Local\Programs\Python\Python39\lib\site-packages\telegram\bot.py", line 2761, in get_updates
    result = self._post(
  File "C:\Users\asus\AppData\Local\Programs\Python\Python39\lib\site-packages\telegram\bot.py", line 259, in _post
    return self.request.post(
  File "C:\Users\asus\AppData\Local\Programs\Python\Python39\lib\site-packages\telegram\utils\request.py", line 350, in post
    result = self._request_wrapper(
  File "C:\Users\asus\AppData\Local\Programs\Python\Python39\lib\site-packages\telegram\utils\request.py", line 277, in _request_wrapper
    raise Conflict(message)
telegram.error.Conflict: Conflict: terminated by other getUpdates request; make sure that only one bot instance is running
ERROR:telegram.ext.updater:Error while getting Updates: Conflict: terminated by other getUpdates request; make sure that only one bot instance is running
ERROR:telegram.ext.dispatcher:No error handlers are registered, logging exception.
Traceback (most recent call last):
  File "C:\Users\asus\AppData\Local\Programs\Python\Python39\lib\site-packages\telegram\ext\updater.py", line 520, in _network_loop_retry
    if not action_cb():
  File "C:\Users\asus\AppData\Local\Programs\Python\Python39\lib\site-packages\telegram\ext\updater.py", line 471, in polling_action_cb
    updates = self.bot.get_updates(
  File "C:\Users\asus\AppData\Local\Programs\Python\Python39\lib\site-packages\telegram\bot.py", line 127, in decorator
    result = func(*args, **kwargs)
  File "C:\Users\asus\AppData\Local\Programs\Python\Python39\lib\site-packages\telegram\bot.py", line 2761, in get_updates
    result = self._post(
  File "C:\Users\asus\AppData\Local\Programs\Python\Python39\lib\site-packages\telegram\bot.py", line 259, in _post
    return self.request.post(
  File "C:\Users\asus\AppData\Local\Programs\Python\Python39\lib\site-packages\telegram\utils\request.py", line 350, in post
    result = self._request_wrapper(
  File "C:\Users\asus\AppData\Local\Programs\Python\Python39\lib\site-packages\telegram\utils\request.py", line 277, in _request_wrapper
    raise Conflict(message)
telegram.error.Conflict: Conflict: terminated by other getUpdates request; make sure that only one bot instance is running
ERROR:telegram.ext.updater:Error while getting Updates: Conflict: terminated by other getUpdates request; make sure that only one bot instance is running
ERROR:telegram.ext.dispatcher:No error handlers are registered, logging exception.
Traceback (most recent call last):
  File "C:\Users\asus\AppData\Local\Programs\Python\Python39\lib\site-packages\telegram\ext\updater.py", line 520, in _network_loop_retry
    if not action_cb():
  File "C:\Users\asus\AppData\Local\Programs\Python\Python39\lib\site-packages\telegram\ext\updater.py", line 471, in polling_action_cb
    updates = self.bot.get_updates(
  File "C:\Users\asus\AppData\Local\Programs\Python\Python39\lib\site-packages\telegram\bot.py", line 127, in decorator
    result = func(*args, **kwargs)
  File "C:\Users\asus\AppData\Local\Programs\Python\Python39\lib\site-packages\telegram\bot.py", line 2761, in get_updates
    result = self._post(
  File "C:\Users\asus\AppData\Local\Programs\Python\Python39\lib\site-packages\telegram\bot.py", line 259, in _post
    return self.request.post(
  File "C:\Users\asus\AppData\Local\Programs\Python\Python39\lib\site-packages\telegram\utils\request.py", line 350, in post
    result = self._request_wrapper(
  File "C:\Users\asus\AppData\Local\Programs\Python\Python39\lib\site-packages\telegram\utils\request.py", line 277, in _request_wrapper
    raise Conflict(message)
telegram.error.Conflict: Conflict: terminated by other getUpdates request; make sure that only one bot instance is running
ERROR:telegram.ext.updater:Error while getting Updates: Conflict: terminated by other getUpdates request; make sure that only one bot instance is running
ERROR:telegram.ext.dispatcher:No error handlers are registered, logging exception.
Traceback (most recent call last):
  File "C:\Users\asus\AppData\Local\Programs\Python\Python39\lib\site-packages\telegram\ext\updater.py", line 520, in _network_loop_retry
    if not action_cb():
  File "C:\Users\asus\AppData\Local\Programs\Python\Python39\lib\site-packages\telegram\ext\updater.py", line 471, in polling_action_cb
    updates = self.bot.get_updates(
  File "C:\Users\asus\AppData\Local\Programs\Python\Python39\lib\site-packages\telegram\bot.py", line 127, in decorator
    result = func(*args, **kwargs)
  File "C:\Users\asus\AppData\Local\Programs\Python\Python39\lib\site-packages\telegram\bot.py", line 2761, in get_updates
    result = self._post(
  File "C:\Users\asus\AppData\Local\Programs\Python\Python39\lib\site-packages\telegram\bot.py", line 259, in _post
    return self.request.post(
  File "C:\Users\asus\AppData\Local\Programs\Python\Python39\lib\site-packages\telegram\utils\request.py", line 350, in post
    result = self._request_wrapper(
  File "C:\Users\asus\AppData\Local\Programs\Python\Python39\lib\site-packages\telegram\utils\request.py", line 277, in _request_wrapper
    raise Conflict(message)
telegram.error.Conflict: Conflict: terminated by other getUpdates request; make sure that only one bot instance is running
ERROR:telegram.ext.updater:Error while getting Updates: Conflict: terminated by other getUpdates request; make sure that only one bot instance is running
ERROR:telegram.ext.dispatcher:No error handlers are registered, logging exception.
Traceback (most recent call last):
  File "C:\Users\asus\AppData\Local\Programs\Python\Python39\lib\site-packages\telegram\ext\updater.py", line 520, in _network_loop_retry
    if not action_cb():
  File "C:\Users\asus\AppData\Local\Programs\Python\Python39\lib\site-packages\telegram\ext\updater.py", line 471, in polling_action_cb
    updates = self.bot.get_updates(
  File "C:\Users\asus\AppData\Local\Programs\Python\Python39\lib\site-packages\telegram\bot.py", line 127, in decorator
    result = func(*args, **kwargs)
  File "C:\Users\asus\AppData\Local\Programs\Python\Python39\lib\site-packages\telegram\bot.py", line 2761, in get_updates
    result = self._post(
  File "C:\Users\asus\AppData\Local\Programs\Python\Python39\lib\site-packages\telegram\bot.py", line 259, in _post
    return self.request.post(
  File "C:\Users\asus\AppData\Local\Programs\Python\Python39\lib\site-packages\telegram\utils\request.py", line 350, in post
    result = self._request_wrapper(
  File "C:\Users\asus\AppData\Local\Programs\Python\Python39\lib\site-packages\telegram\utils\request.py", line 277, in _request_wrapper
    raise Conflict(message)
telegram.error.Conflict: Conflict: terminated by other getUpdates request; make sure that only one bot instance is running
ERROR:telegram.ext.updater:Error while getting Updates: Conflict: terminated by other getUpdates request; make sure that only one bot instance is running
ERROR:telegram.ext.dispatcher:No error handlers are registered, logging exception.
Traceback (most recent call last):
  File "C:\Users\asus\AppData\Local\Programs\Python\Python39\lib\site-packages\telegram\ext\updater.py", line 520, in _network_loop_retry
    if not action_cb():
  File "C:\Users\asus\AppData\Local\Programs\Python\Python39\lib\site-packages\telegram\ext\updater.py", line 471, in polling_action_cb
    updates = self.bot.get_updates(
  File "C:\Users\asus\AppData\Local\Programs\Python\Python39\lib\site-packages\telegram\bot.py", line 127, in decorator
    result = func(*args, **kwargs)
  File "C:\Users\asus\AppData\Local\Programs\Python\Python39\lib\site-packages\telegram\bot.py", line 2761, in get_updates
    result = self._post(
  File "C:\Users\asus\AppData\Local\Programs\Python\Python39\lib\site-packages\telegram\bot.py", line 259, in _post
    return self.request.post(
  File "C:\Users\asus\AppData\Local\Programs\Python\Python39\lib\site-packages\telegram\utils\request.py", line 350, in post
    result = self._request_wrapper(
  File "C:\Users\asus\AppData\Local\Programs\Python\Python39\lib\site-packages\telegram\utils\request.py", line 277, in _request_wrapper
    raise Conflict(message)
telegram.error.Conflict: Conflict: terminated by other getUpdates request; make sure that only one bot instance is running
ERROR:telegram.ext.updater:Error while getting Updates: Conflict: terminated by other getUpdates request; make sure that only one bot instance is running
ERROR:telegram.ext.dispatcher:No error handlers are registered, logging exception.
Traceback (most recent call last):
  File "C:\Users\asus\AppData\Local\Programs\Python\Python39\lib\site-packages\telegram\ext\updater.py", line 520, in _network_loop_retry
    if not action_cb():
  File "C:\Users\asus\AppData\Local\Programs\Python\Python39\lib\site-packages\telegram\ext\updater.py", line 471, in polling_action_cb
    updates = self.bot.get_updates(
  File "C:\Users\asus\AppData\Local\Programs\Python\Python39\lib\site-packages\telegram\bot.py", line 127, in decorator
    result = func(*args, **kwargs)
  File "C:\Users\asus\AppData\Local\Programs\Python\Python39\lib\site-packages\telegram\bot.py", line 2761, in get_updates
    result = self._post(
  File "C:\Users\asus\AppData\Local\Programs\Python\Python39\lib\site-packages\telegram\bot.py", line 259, in _post
    return self.request.post(
  File "C:\Users\asus\AppData\Local\Programs\Python\Python39\lib\site-packages\telegram\utils\request.py", line 350, in post
    result = self._request_wrapper(
  File "C:\Users\asus\AppData\Local\Programs\Python\Python39\lib\site-packages\telegram\utils\request.py", line 277, in _request_wrapper
    raise Conflict(message)
telegram.error.Conflict: Conflict: terminated by other getUpdates request; make sure that only one bot instance is running
ERROR:telegram.ext.updater:Error while getting Updates: Conflict: terminated by other getUpdates request; make sure that only one bot instance is running
ERROR:telegram.ext.dispatcher:No error handlers are registered, logging exception.
Traceback (most recent call last):
  File "C:\Users\asus\AppData\Local\Programs\Python\Python39\lib\site-packages\telegram\ext\updater.py", line 520, in _network_loop_retry
    if not action_cb():
  File "C:\Users\asus\AppData\Local\Programs\Python\Python39\lib\site-packages\telegram\ext\updater.py", line 471, in polling_action_cb
    updates = self.bot.get_updates(
  File "C:\Users\asus\AppData\Local\Programs\Python\Python39\lib\site-packages\telegram\bot.py", line 127, in decorator
    result = func(*args, **kwargs)
  File "C:\Users\asus\AppData\Local\Programs\Python\Python39\lib\site-packages\telegram\bot.py", line 2761, in get_updates
    result = self._post(
  File "C:\Users\asus\AppData\Local\Programs\Python\Python39\lib\site-packages\telegram\bot.py", line 259, in _post
    return self.request.post(
  File "C:\Users\asus\AppData\Local\Programs\Python\Python39\lib\site-packages\telegram\utils\request.py", line 350, in post
    result = self._request_wrapper(
  File "C:\Users\asus\AppData\Local\Programs\Python\Python39\lib\site-packages\telegram\utils\request.py", line 277, in _request_wrapper
    raise Conflict(message)
telegram.error.Conflict: Conflict: terminated by other getUpdates request; make sure that only one bot instance is running
ERROR:telegram.ext.updater:Error while getting Updates: Conflict: terminated by other getUpdates request; make sure that only one bot instance is running
ERROR:telegram.ext.dispatcher:No error handlers are registered, logging exception.
Traceback (most recent call last):
  File "C:\Users\asus\AppData\Local\Programs\Python\Python39\lib\site-packages\telegram\ext\updater.py", line 520, in _network_loop_retry
    if not action_cb():
  File "C:\Users\asus\AppData\Local\Programs\Python\Python39\lib\site-packages\telegram\ext\updater.py", line 471, in polling_action_cb
    updates = self.bot.get_updates(
  File "C:\Users\asus\AppData\Local\Programs\Python\Python39\lib\site-packages\telegram\bot.py", line 127, in decorator
    result = func(*args, **kwargs)
  File "C:\Users\asus\AppData\Local\Programs\Python\Python39\lib\site-packages\telegram\bot.py", line 2761, in get_updates
    result = self._post(
  File "C:\Users\asus\AppData\Local\Programs\Python\Python39\lib\site-packages\telegram\bot.py", line 259, in _post
    return self.request.post(
  File "C:\Users\asus\AppData\Local\Programs\Python\Python39\lib\site-packages\telegram\utils\request.py", line 350, in post
    result = self._request_wrapper(
  File "C:\Users\asus\AppData\Local\Programs\Python\Python39\lib\site-packages\telegram\utils\request.py", line 277, in _request_wrapper
    raise Conflict(message)
telegram.error.Conflict: Conflict: terminated by other getUpdates request; make sure that only one bot instance is running
ERROR:telegram.ext.updater:Error while getting Updates: Conflict: terminated by other getUpdates request; make sure that only one bot instance is running
ERROR:telegram.ext.dispatcher:No error handlers are registered, logging exception.
Traceback (most recent call last):
  File "C:\Users\asus\AppData\Local\Programs\Python\Python39\lib\site-packages\telegram\ext\updater.py", line 520, in _network_loop_retry
    if not action_cb():
  File "C:\Users\asus\AppData\Local\Programs\Python\Python39\lib\site-packages\telegram\ext\updater.py", line 471, in polling_action_cb
    updates = self.bot.get_updates(
  File "C:\Users\asus\AppData\Local\Programs\Python\Python39\lib\site-packages\telegram\bot.py", line 127, in decorator
    result = func(*args, **kwargs)
  File "C:\Users\asus\AppData\Local\Programs\Python\Python39\lib\site-packages\telegram\bot.py", line 2761, in get_updates
    result = self._post(
  File "C:\Users\asus\AppData\Local\Programs\Python\Python39\lib\site-packages\telegram\bot.py", line 259, in _post
    return self.request.post(
  File "C:\Users\asus\AppData\Local\Programs\Python\Python39\lib\site-packages\telegram\utils\request.py", line 350, in post
    result = self._request_wrapper(
  File "C:\Users\asus\AppData\Local\Programs\Python\Python39\lib\site-packages\telegram\utils\request.py", line 277, in _request_wrapper
    raise Conflict(message)
telegram.error.Conflict: Conflict: terminated by other getUpdates request; make sure that only one bot instance is running
ERROR:telegram.ext.updater:Error while getting Updates: Conflict: terminated by other getUpdates request; make sure that only one bot instance is running
ERROR:telegram.ext.dispatcher:No error handlers are registered, logging exception.
Traceback (most recent call last):
  File "C:\Users\asus\AppData\Local\Programs\Python\Python39\lib\site-packages\telegram\ext\updater.py", line 520, in _network_loop_retry
    if not action_cb():
  File "C:\Users\asus\AppData\Local\Programs\Python\Python39\lib\site-packages\telegram\ext\updater.py", line 471, in polling_action_cb
    updates = self.bot.get_updates(
  File "C:\Users\asus\AppData\Local\Programs\Python\Python39\lib\site-packages\telegram\bot.py", line 127, in decorator
    result = func(*args, **kwargs)
  File "C:\Users\asus\AppData\Local\Programs\Python\Python39\lib\site-packages\telegram\bot.py", line 2761, in get_updates
    result = self._post(
  File "C:\Users\asus\AppData\Local\Programs\Python\Python39\lib\site-packages\telegram\bot.py", line 259, in _post
    return self.request.post(
  File "C:\Users\asus\AppData\Local\Programs\Python\Python39\lib\site-packages\telegram\utils\request.py", line 350, in post
    result = self._request_wrapper(
  File "C:\Users\asus\AppData\Local\Programs\Python\Python39\lib\site-packages\telegram\utils\request.py", line 277, in _request_wrapper
    raise Conflict(message)
telegram.error.Conflict: Conflict: terminated by other getUpdates request; make sure that only one bot instance is running
ERROR:telegram.ext.updater:Error while getting Updates: Conflict: terminated by other getUpdates request; make sure that only one bot instance is running
ERROR:telegram.ext.dispatcher:No error handlers are registered, logging exception.
Traceback (most recent call last):
  File "C:\Users\asus\AppData\Local\Programs\Python\Python39\lib\site-packages\telegram\ext\updater.py", line 520, in _network_loop_retry
    if not action_cb():
  File "C:\Users\asus\AppData\Local\Programs\Python\Python39\lib\site-packages\telegram\ext\updater.py", line 471, in polling_action_cb
    updates = self.bot.get_updates(
  File "C:\Users\asus\AppData\Local\Programs\Python\Python39\lib\site-packages\telegram\bot.py", line 127, in decorator
    result = func(*args, **kwargs)
  File "C:\Users\asus\AppData\Local\Programs\Python\Python39\lib\site-packages\telegram\bot.py", line 2761, in get_updates
    result = self._post(
  File "C:\Users\asus\AppData\Local\Programs\Python\Python39\lib\site-packages\telegram\bot.py", line 259, in _post
    return self.request.post(
  File "C:\Users\asus\AppData\Local\Programs\Python\Python39\lib\site-packages\telegram\utils\request.py", line 350, in post
    result = self._request_wrapper(
  File "C:\Users\asus\AppData\Local\Programs\Python\Python39\lib\site-packages\telegram\utils\request.py", line 277, in _request_wrapper
    raise Conflict(message)
telegram.error.Conflict: Conflict: terminated by other getUpdates request; make sure that only one bot instance is running
ERROR:telegram.ext.updater:Error while getting Updates: Conflict: terminated by other getUpdates request; make sure that only one bot instance is running
ERROR:telegram.ext.dispatcher:No error handlers are registered, logging exception.
Traceback (most recent call last):
  File "C:\Users\asus\AppData\Local\Programs\Python\Python39\lib\site-packages\telegram\ext\updater.py", line 520, in _network_loop_retry
    if not action_cb():
  File "C:\Users\asus\AppData\Local\Programs\Python\Python39\lib\site-packages\telegram\ext\updater.py", line 471, in polling_action_cb
    updates = self.bot.get_updates(
  File "C:\Users\asus\AppData\Local\Programs\Python\Python39\lib\site-packages\telegram\bot.py", line 127, in decorator
    result = func(*args, **kwargs)
  File "C:\Users\asus\AppData\Local\Programs\Python\Python39\lib\site-packages\telegram\bot.py", line 2761, in get_updates
    result = self._post(
  File "C:\Users\asus\AppData\Local\Programs\Python\Python39\lib\site-packages\telegram\bot.py", line 259, in _post
    return self.request.post(
  File "C:\Users\asus\AppData\Local\Programs\Python\Python39\lib\site-packages\telegram\utils\request.py", line 350, in post
    result = self._request_wrapper(
  File "C:\Users\asus\AppData\Local\Programs\Python\Python39\lib\site-packages\telegram\utils\request.py", line 277, in _request_wrapper
    raise Conflict(message)
telegram.error.Conflict: Conflict: terminated by other getUpdates request; make sure that only one bot instance is running
ERROR:telegram.ext.updater:Error while getting Updates: Conflict: terminated by other getUpdates request; make sure that only one bot instance is running
ERROR:telegram.ext.dispatcher:No error handlers are registered, logging exception.
Traceback (most recent call last):
  File "C:\Users\asus\AppData\Local\Programs\Python\Python39\lib\site-packages\telegram\ext\updater.py", line 520, in _network_loop_retry
    if not action_cb():
  File "C:\Users\asus\AppData\Local\Programs\Python\Python39\lib\site-packages\telegram\ext\updater.py", line 471, in polling_action_cb
    updates = self.bot.get_updates(
  File "C:\Users\asus\AppData\Local\Programs\Python\Python39\lib\site-packages\telegram\bot.py", line 127, in decorator
    result = func(*args, **kwargs)
  File "C:\Users\asus\AppData\Local\Programs\Python\Python39\lib\site-packages\telegram\bot.py", line 2761, in get_updates
    result = self._post(
  File "C:\Users\asus\AppData\Local\Programs\Python\Python39\lib\site-packages\telegram\bot.py", line 259, in _post
    return self.request.post(
  File "C:\Users\asus\AppData\Local\Programs\Python\Python39\lib\site-packages\telegram\utils\request.py", line 350, in post
    result = self._request_wrapper(
  File "C:\Users\asus\AppData\Local\Programs\Python\Python39\lib\site-packages\telegram\utils\request.py", line 277, in _request_wrapper
    raise Conflict(message)
telegram.error.Conflict: Conflict: terminated by other getUpdates request; make sure that only one bot instance is running
ERROR:telegram.ext.updater:Error while getting Updates: Conflict: terminated by other getUpdates request; make sure that only one bot instance is running
ERROR:telegram.ext.dispatcher:No error handlers are registered, logging exception.
Traceback (most recent call last):
  File "C:\Users\asus\AppData\Local\Programs\Python\Python39\lib\site-packages\telegram\ext\updater.py", line 520, in _network_loop_retry
    if not action_cb():
  File "C:\Users\asus\AppData\Local\Programs\Python\Python39\lib\site-packages\telegram\ext\updater.py", line 471, in polling_action_cb
    updates = self.bot.get_updates(
  File "C:\Users\asus\AppData\Local\Programs\Python\Python39\lib\site-packages\telegram\bot.py", line 127, in decorator
    result = func(*args, **kwargs)
  File "C:\Users\asus\AppData\Local\Programs\Python\Python39\lib\site-packages\telegram\bot.py", line 2761, in get_updates
    result = self._post(
  File "C:\Users\asus\AppData\Local\Programs\Python\Python39\lib\site-packages\telegram\bot.py", line 259, in _post
    return self.request.post(
  File "C:\Users\asus\AppData\Local\Programs\Python\Python39\lib\site-packages\telegram\utils\request.py", line 350, in post
    result = self._request_wrapper(
  File "C:\Users\asus\AppData\Local\Programs\Python\Python39\lib\site-packages\telegram\utils\request.py", line 277, in _request_wrapper
    raise Conflict(message)
telegram.error.Conflict: Conflict: terminated by other getUpdates request; make sure that only one bot instance is running
INFO:telegram.ext.updater:Received signal 2 (SIGINT), stopping...
INFO:apscheduler.scheduler:Scheduler has been shut down
